<mujoco>
    <option timestep="0.00001">
		<flag gravity="enable"/>
        <!-- <flag gravity="disable"/> -->
    </option>
    
    <worldbody>
        <light diffuse=".5 .5 .5" pos="0 0 3" dir="0 0 -1"/>
        <geom type="plane" size="1 1 0.1" rgba=".9 0 0 1" pos="0 0 -0.4"/>
        <site name="s0" pos="0 0 2" size="0.02"/>
        <body pos="0 0 1.28" euler="0 0 0">
            <joint name="mSlide" type="slide" axis="0 0 1" pos="0 0 3" range="-2 2" damping="20"/>
            <!-- <joint name="mSlide" type="slide" axis="0 0 1" pos="0 0 3" range="-2 2"/> -->
            <geom  type="box" size="0.1 0.1 0.1" rgba="0 1 0 1" mass="1"/>
            <site name="s1" pos="0 0 0.12" size="0.02"/>
        </body>
    </worldbody>
    
    <tendon>
        <spatial name="mTendon" width="0.01">
            <site site="s0"/>
            <site site="s1"/>
        </spatial>
    </tendon>
    
    <actuator>
        <position name="mPos" joint="mSlide" kp="50" ctrlrange="-4 4"/>
        <muscle name="mMuscle" tendon="mTendon" lengthrange="0 2" ctrlrange="-2 2"/>
    </actuator>
</mujoco>